Workbook

Sheet Cocktails
A1: name | B1: description | C1: ingredients | D1: timesMade | E1: images | F1: Alcohol Content (ml) | G1: ABV
A2: Abbey | B2: A classic cocktail and the first drink in The Savoy Cocktail Book from 1930. Still well known in Britain, it blends gin, Lillet Blanc, orange juice, and a dash of orange bitters. | C2: Gin – 45 ml Lillet Blanc – 20 ml Orange Juice – 20 ml Orange Bitters – 2 dash Cherry – 1 | D2: 8 | E2: images/cocktails/abbey.jpg | F2: 21.4 | G2: 0.252
A3: Adam & Eve | B3: This variation on the Old Fashioned gets a pleasant herbal kick from Galliano liqueur, adding vanilla and anise notes to the bourbon base with simple syrup and Angostura bitters. | C3: Bourbon – 60 ml Galliano – 15 ml Simple Syrup – 7 ml Angostura Bitters – 3 dash | D3: 5 | E3: images/cocktails/adam-eve.jpg | F3: 30.4 | G3: 0.371
A4: Adonis | B4: The Adonis cocktail was most likely named after a play (the first Broadway play to run more than 500 shows) in the 19th century, which was also a time when sherry was extremely popular. | C4: Dry Sherry – 45 ml Sweet Vermouth – 20 ml Orange Bitters – 1 dash Orange Peel – 1 | D4: 0 | E4: images/cocktails/adonis.jpg | F4: 10.9 | G4: 0.168
A5: Airmail | B5: A rum-based champagne cocktail likely created in 1930s Cuba, possibly by Bacardi to celebrate the launch of airmail service. Published in Esquire's 1949 Handbook for Hosts. | C5: Rum – 60 ml Lime Juice – 15 ml Honey – 5.0 ml Sparkling Wine – 150 ml | D5: 3 | E5: images/cocktails/airmail.jpg | F5: 42 | G5: 0.183
A6: Alabama Slammer | B6: Also sometimes known as a Southern Slammer, this fruity drink was popular in the 1980s and was often available in pitcher size at chain restaurants. It blends vodka with amaretto and Southern Comfort. | C6: Vodka – 45 ml Orange Juice – 30 ml Amaretto – 15 ml Southern Comfort – 15 ml Grenadine – 7 ml Orange – 1 slice | D6: 0 | E6: images/cocktails/alabama-slammer.jpg | F6: 27.5 | G6: 0.246
A7: Alaska | B7: A variation on the martini replacing dry vermouth with yellow Chartreuse, a liqueur produced by Carthusian monks in France. A classic cocktail dating to the early 20th century. | C7: Gin – 60 ml Yellow Chartreuse – 15 ml | D7: 1 | E7: images/cocktails/alaska.jpg | F7: 30 | G7: 0.4
A8: Alfonso | B8: Named after Spanish King Alfonso XIII, who is said to have tried this cocktail while in France. A sugar cube soaked in Angostura bitters is topped with Dubonnet and sparkling wine. | C8: Sugar Cube – 1 Angostura Bitters – 4 dash Dubonnet – 15 ml Sparkling Wine – 120 ml | D8: 1 | E8: images/cocktails/alfonso.jpg | F8: 16.6 | G8: 0.123
A9: Algonquin | B9: Named for the famed Algonquin Hotel in New York City. Since the hotel didn't serve alcohol until after Prohibition, this rye, vermouth, and pineapple cocktail likely dates to the mid-1930s. | C9: Rye – 60 ml Dry Vermouth – 30 ml Pineapple Juice – 30 ml Cherry – 1 | D9: 0 | E9: images/cocktails/algonquin.jpg | F9: 29.4 | G9: 0.245
A10: Amaretto Sour | B10: A smooth, sweet cocktail ideal for those who prefer an easy-drinking drink. The almond-flavored amaretto is balanced by fresh lemon juice for a simple yet satisfying sour. | C10: Amaretto – 60 ml Lemon Juice – 30 ml Lemon – 1 wedge Cherry – 1 | D10: 5 | E10: images/cocktails/amaretto-sour.jpg | F10: 16.8 | G10: 0.187
A11: American Variation | B11: Based on the American Trilogy cocktail from Little Branch in New York City. A nice combination of rye whiskey, Grand Marnier, apple brandy, and both Angostura and Peychaud's bitters. | C11: Rye – 60 ml Grand Marnier – 15 ml Apple Brandy – 15 ml Angostura Bitters – 1 dash Peychaud's Bitters – 1 dash Lemon Peel – 1 twist | D11: 1 | E11: images/cocktails/american-variation.jpg | F11: 36 | G11: 0.4
A12: Americana | B12: A very pleasant sparkling cocktail where smooth Tennessee whiskey meets champagne. A sugar cube soaked in Angostura bitters adds depth to this elegant, celebratory drink. | C12: Sugar Cube – 1 Angostura Bitters – 4 dash Tennessee Whiskey – 30 ml Sparkling Wine – 150 ml | D12: 1 | E12: images/cocktails/americana.jpg | F12: 30 | G12: 0.167
A13: Americano | B13: Originally dubbed the Americano because of its popularity with US tourists in Italy during Prohibition. The recipe was created at Gaspare's Campari Bar in Turin in 1861. | C13: Campari – 45 ml Sweet Vermouth – 45 ml Club Soda – 90 ml Orange Peel – 1 | D13: 1 | E13: images/cocktails/americano.jpg | F13: 18.5 | G13: 0.103
... A161: Paper Plane | B161: Created by star New York bartender Sam Ross, named after the M.I.A. song he listened to while inventing it. Equal parts bourbon, lemon juice, Aperol, and amaro make a bittersweet modern classic. | C161: Bourbon – 20 ml Lemon Juice – 20 ml Aperol – 20 ml Amaro – 20 ml | D161: 1 | E161: images/cocktails/paper-plane.jpg | F161: 16.2 | G161: 0.202
A162: Pegu Club | B162: The signature drink of the Pegu Club, a long closed gentlemen's club in Rangoon, Burma. The cocktail is now served at the Pegu Club bar in New York City's SoHo district. | C162: Gin – 52 ml Triple Sec – 22 ml Lime Juice – 15 ml Orange Bitters – 1 dash Angostura Bitters – 1 dash | D162: 0 | E162: images/cocktails/pegu-club.jpg | F162: =ROUND(52*'Alcohol by Category'!$E$14+22*'Alcohol by Category'!$E$50,1) -> 27.4 | G162: =ROUND(F162/(52+22+15),3) -> 0.308
A163: Penicillin | B163: A modern classic created by New York bartender Sam Ross. Scotch whisky is combined with honey, lemon juice, and ginger for a soothing, warming cocktail that's a cure for a chilly night. | C163: Scotch Whiskey – 50 ml Lemon Juice – 20 ml Ginger Syrup – 10 ml Honey – 5 ml | D163: 5 | E163: images/cocktails/penicillin.jpg | F163: 20 | G163: 0.235
A164: Penja #22 | B164: A tailor-made cocktail recipe created and shared by a fellow home mixologist. White Penja pepper syrup is combined with beer in this unusual, spice-forward drink from Cameroon's pepper region. | C164: Paragon White Penja Pepper – 15 ml Beer – 100 ml | D164: 1 | E164: images/cocktails/penja-22.jpg | F164: 5 | G164: 0.043
A165: Perfect Rob Roy | B165: Created at the Waldorf Astoria in 1894 for the operetta Rob Roy. Similar to a Manhattan but with Scotch; the Perfect version uses equal parts sweet and dry vermouth for balanced complexity. | C165: Scotch Whiskey – 75 ml Dry Vermouth – 15 ml Sweet Vermouth – 15 ml Angostura Bitters – 2 dash Lemon Peel – 1 | D165: 5 | E165: images/cocktails/perfect-rob-roy.jpg | F165: 35.1 | G165: 0.334
A166: Pimm's Cup | B166: A refreshing summer drink popular in Great Britain and closely associated with New Orleans, where it's the house drink at the Napoleon House. Pimm's No. 1, lemon, and ginger ale over ice. | C166: Pimm's No. 1 – 60 ml Lemon Juice – 15 ml Ginger Ale – 120 ml Cucumber – 1 slice | D166: 3 | E166: images/cocktails/pimm-s-cup.jpg | F166: 15 | G166: 0.077
A167: Pisco Sour | B167: Created in Lima, Peru by American bartender Victor Morris in the early 1920s. The Pisco Sour is the national drink of both Peru and Chile, featuring pisco, lime, egg white, and bitters. | C167: Egg white – 30 ml Pisco – 60 ml Lime Juice – 20 ml Simple Syrup – 15 ml Angostura Bitters – 4 dash | D167: 15 | E167: images/cocktails/pisco-sour.jpg | F167: 24 | G167: 0.192
A168: Pompadour | B168: Mentioned in Philippe Collin's 2024 novel Le Barman du Ritz. Created by Frank Meier at the Ritz, it combines Pineau des Charentes, light rum, and lemon juice for an extraordinary flavor. | C168: Pineau des Charentes – 45 ml Light Rum – 45 ml Lemon Juice – 15 ml | D168: 5 | E168: images/cocktails/pompadour.jpg | F168: 25.9 | G168: 0.247
A169: Preakness | B169: A complex variation on the Manhattan accented with richly herbal Benedictine liqueur. Rye whiskey, sweet vermouth, and Angostura bitters round out this classic horse-racing-themed cocktail. | C169: Rye – 45 ml Sweet Vermouth – 20 ml Benedictine – 7 ml Angostura Bitters – 2 dash Cherry – 1 | D169: 0 | E169: images/cocktails/preakness.jpg | F169: 24 | G169: 0.333
A170: Queen Bee | B170: Created by Neil Kopplin of the Carlyle Restaurant in Portland, Oregon. Vodka, lemon juice, St. Germain, and honey syrup are shaken and topped with sparkling wine for a floral, elegant fizz. | C170: Vodka – 20 ml Lemon Juice – 20 ml St. Germain – 20 ml Honey Syrup – 7 ml Sparkling Wine – 30 ml Orange Peel – 1 | D170: 2 | E170: images/cocktails/queen-bee.jpg | F170: 15.6 | G170: 0.161
A171: Queen Elizabeth | B171: Named after its Philadelphia creator's wife, not the queen of England. Dating from just after Prohibition, it combines dry vermouth, Benedictine, and lime juice for an herbal sipper. | C171: Dry Vermouth – 45 ml Benedictine – 20 ml Lime Juice – 20 ml | D171: 12 | E171: images/cocktails/queen-elizabeth.jpg | F171: 16.1 | G171: 0.189
A172: Rainbow Dee-Lite | B172: A layered cocktail from Dee Brun, the Cocktail Diva. After impressing your audience with the stunning visuals of blue curaçao, grenadine, and juices, stir to blend all the flavors. | C172: Blue Curacao – 30 ml Vodka – 30 ml Grenadine – 30 ml Orange Juice – 60 ml Pineapple Juice – 30 ml | D172: 0 | E172: images/cocktails/rainbow-dee-lite.jpg | F172: 19.5 | G172: 0.108
A173: Ramos Gin Fizz | B173: Invented by Henry C. Ramos in New Orleans. The key is shaking with ice for 1-2 minutes for a silky texture. Gin, citrus, egg white, cream, and orange flower water create an iconic, frothy drink. | C173: Egg white – 15 ml Gin – 60 ml Lemon Juice – 15 ml Lime Juice – 15 ml Simple Syrup – 30 ml Orange-Flower Water – 3 drop | D173: 10 | E173: images/cocktails/ramos-gin-fizz.jpg | F173: 24 | G173: 0.178
A174: Raspberry Silver Fizz | B174: From Harry Johnson's 1882 New and Improved Bartender's Manual. Gin, raspberry liqueur, lime juice, and egg white are shaken and topped with club soda for a fruity, frothy fizz. | C174: Egg white – 15 ml Gin – 45 ml Raspberry Liqueur – 15 ml Simple Syrup – 8 ml Lime Juice – 15 ml Club Soda – 60 ml | D174: 7 | E174: images/cocktails/raspberry-silver-fizz.jpg | F174: 21 | G174: 0.133
... A199: Spritz | B199: An Italian wine-based cocktail commonly served as an aperitif in Northeast Italy. Prosecco, Aperol, and soda water combine in this light, refreshing, bittersweet drink now popular worldwide. | C199: Aperol – 40 ml Sparkling Wine – 60 ml Club Soda – 20 ml | D199: 115 | E199: images/cocktails/spritz.jpg | F199: 11.6 | G199: 0.097
A200: Spritz Averna | B200: A Spritz version with Averna, an Italian liqueur in the amaro category produced in Caltanissetta, Italy | C200: Averna – 40 ml Sparkling Wine – 60 ml Club Soda – 20 ml | D200: 0 | E200: images/cocktails/spritzaverna.jpg | F200: {=ROUND(SUM(_xlfn.LET(_xlpm.lines,_xlfn.TEXTSPLIT(C200,,CHAR(10)),_xlpm.nm,TRIM(_xlfn.TEXTBEFORE(_xlpm.lines," – ")),_xlpm.amt,VALUE(_xlfn.TEXTBEFORE(_xlfn.TEXTAFTER(_xlpm.lines," – ")," ")),_xlpm.abv,_xlfn.IFNA(_xlfn.XLOOKUP(_xlpm.nm,'Alcohol by Category'!$A$13:$A$95,'Alcohol by Category'!$E$13:$E$95),_xlfn.IFNA(_xlfn.XLOOKUP(_xlpm.nm,'Alcohol by Category'!$A$99:$A$107,'Alcohol by Category'!$E$99:$E$107),0)),_xlpm.amt*_xlpm.abv)),1)} -> 18.8 | G200: {=ROUND(F200/SUM(_xlfn.LET(_xlpm.lines,_xlfn.TEXTSPLIT(C200,,CHAR(10)),_xlpm.amt,VALUE(_xlfn.TEXTBEFORE(_xlfn.TEXTAFTER(_xlpm.lines," – ")," ")),_xlpm.amt)),3)} -> 0.157
A201: Spritz Campari | B201: A Spritz version with Campari, the famous Italian bitter characterised by its dark red colour | C201: Campari – 40 ml Sparkling Wine – 60 ml Club Soda – 20 ml | D201: 1 | E201: images/cocktails/spritzcampari.jpg | F201: {=ROUND(SUM(_xlfn.LET(_xlpm.lines,_xlfn.TEXTSPLIT(C201,,CHAR(10)),_xlpm.nm,TRIM(_xlfn.TEXTBEFORE(_xlpm.lines," – ")),_xlpm.amt,VALUE(_xlfn.TEXTBEFORE(_xlfn.TEXTAFTER(_xlpm.lines," – ")," ")),_xlpm.abv,_xlfn.IFNA(_xlfn.XLOOKUP(_xlpm.nm,'Alcohol by Category'!$A$13:$A$95,'Alcohol by Category'!$E$13:$E$95),_xlfn.IFNA(_xlfn.XLOOKUP(_xlpm.nm,'Alcohol by Category'!$A$99:$A$107,'Alcohol by Category'!$E$99:$E$107),0)),_xlpm.amt*_xlpm.abv)),1)} -> 17.2 | G201: {=ROUND(F201/SUM(_xlfn.LET(_xlpm.lines,_xlfn.TEXTSPLIT(C201,,CHAR(10)),_xlpm.amt,VALUE(_xlfn.TEXTBEFORE(_xlfn.TEXTAFTER(_xlpm.lines," – ")," ")),_xlpm.amt)),3)} -> 0.143
A202: Spritz Cynar | B202: A Spritz version with Cynar, an Italian bitter apéritif of the amaro variety. It is made from 13 herbs and plants, predominantly artichoke (Cynara scolymus), from which the drink derives its name | C202: Cynar – 40 ml Sparkling Wine – 60 ml Club Soda – 20 ml | D202: 3 | E202: images/cocktails/spritzcynar.jpg | F202: {=ROUND(SUM(_xlfn.LET(_xlpm.lines,_xlfn.TEXTSPLIT(C202,,CHAR(10)),_xlpm.nm,TRIM(_xlfn.TEXTBEFORE(_xlpm.lines," – ")),_xlpm.amt,VALUE(_xlfn.TEXTBEFORE(_xlfn.TEXTAFTER(_xlpm.lines," – ")," ")),_xlpm.abv,_xlfn.IFNA(_xlfn.XLOOKUP(_xlpm.nm,'Alcohol by Category'!$A$13:$A$95,'Alcohol by Category'!$E$13:$E$95),_xlfn.IFNA(_xlfn.XLOOKUP(_xlpm.nm,'Alcohol by Category'!$A$99:$A$107,'Alcohol by Category'!$E$99:$E$107),0)),_xlpm.amt*_xlpm.abv)),1)} -> 13.8 | G202: {=ROUND(F202/SUM(_xlfn.LET(_xlpm.lines,_xlfn.TEXTSPLIT(C202,,CHAR(10)),_xlpm.amt,VALUE(_xlfn.TEXTBEFORE(_xlfn.TEXTAFTER(_xlpm.lines," – ")," ")),_xlpm.amt)),3)} -> 0.115
A203: Spritz Immortelle | B203: A Spritz version with Spritz des Dunes, a bitter from Corsica with Immortelle flowers | C203: Spritz des Dunes – 40 ml Sparkling Wine – 60 ml Club Soda – 20 ml | D203: 3 | E203: images/cocktails/spritzimmortelle.jpg | F203: {=ROUND(SUM(_xlfn.LET(_xlpm.lines,_xlfn.TEXTSPLIT(C203,,CHAR(10)),_xlpm.nm,TRIM(_xlfn.TEXTBEFORE(_xlpm.lines," – ")),_xlpm.amt,VALUE(_xlfn.TEXTBEFORE(_xlfn.TEXTAFTER(_xlpm.lines," – ")," ")),_xlpm.abv,_xlfn.IFNA(_xlfn.XLOOKUP(_xlpm.nm,'Alcohol by Category'!$A$13:$A$95,'Alcohol by Category'!$E$13:$E$95),_xlfn.IFNA(_xlfn.XLOOKUP(_xlpm.nm,'Alcohol by Category'!$A$99:$A$107,'Alcohol by Category'!$E$99:$E$107),0)),_xlpm.amt*_xlpm.abv)),1)} -> 15.2 | G203: {=ROUND(F203/SUM(_xlfn.LET(_xlpm.lines,_xlfn.TEXTSPLIT(C203,,CHAR(10)),_xlpm.amt,VALUE(_xlfn.TEXTBEFORE(_xlfn.TEXTAFTER(_xlpm.lines," – ")," ")),_xlpm.amt)),3)} -> 0.127
A204: Spritz Italicus | B204: A Spritz version with Italicus, a bergamot rosolio (a type of aperitivo) manufactured in Italy. The liqueur uses bergamot from Calabria and citrons from Sicily, along with Italian flower varieties. | C204: Italicus – 40 ml Sparkling Wine – 60 ml Club Soda – 20 ml | D204: 0 | E204: images/cocktails/spritzitalicus.jpg | F204: {=ROUND(SUM(_xlfn.LET(_xlpm.lines,_xlfn.TEXTSPLIT(C204,,CHAR(10)),_xlpm.nm,TRIM(_xlfn.TEXTBEFORE(_xlpm.lines," – ")),_xlpm.amt,VALUE(_xlfn.TEXTBEFORE(_xlfn.TEXTAFTER(_xlpm.lines," – ")," ")),_xlpm.abv,_xlfn.IFNA(_xlfn.XLOOKUP(_xlpm.nm,'Alcohol by Category'!$A$13:$A$95,'Alcohol by Category'!$E$13:$E$95),_xlfn.IFNA(_xlfn.XLOOKUP(_xlpm.nm,'Alcohol by Category'!$A$99:$A$107,'Alcohol by Category'!$E$99:$E$107),0)),_xlpm.amt*_xlpm.abv)),1)} -> 15.2 | G204: {=ROUND(F204/SUM(_xlfn.LET(_xlpm.lines,_xlfn.TEXTSPLIT(C204,,CHAR(10)),_xlpm.amt,VALUE(_xlfn.TEXTBEFORE(_xlfn.TEXTAFTER(_xlpm.lines," – ")," ")),_xlpm.amt)),3)} -> 0.127
A205: Spritz Limoncello | B205: A Spritz version with Limoncello, a liqueur made from the zest of lemons. | C205: Lilmoncello – 40 ml Sparkling Wine – 60 ml Club Soda – 20 ml | D205: 0 | E205: images/cocktails/spritzlimoncello.jpg | F205: {=ROUND(SUM(_xlfn.LET(_xlpm.lines,_xlfn.TEXTSPLIT(C205,,CHAR(10)),_xlpm.nm,TRIM(_xlfn.TEXTBEFORE(_xlpm.lines," – ")),_xlpm.amt,VALUE(_xlfn.TEXTBEFORE(_xlfn.TEXTAFTER(_xlpm.lines," – ")," ")),_xlpm.abv,_xlfn.IFNA(_xlfn.XLOOKUP(_xlpm.nm,'Alcohol by Category'!$A$13:$A$95,'Alcohol by Category'!$E$13:$E$95),_xlfn.IFNA(_xlfn.XLOOKUP(_xlpm.nm,'Alcohol by Category'!$A$99:$A$107,'Alcohol by Category'!$E$99:$E$107),0)),_xlpm.amt*_xlpm.abv)),1)} -> 19.2 | G205: {=ROUND(F205/SUM(_xlfn.LET(_xlpm.lines,_xlfn.TEXTSPLIT(C205,,CHAR(10)),_xlpm.amt,VALUE(_xlfn.TEXTBEFORE(_xlfn.TEXTAFTER(_xlpm.lines," – ")," ")),_xlpm.amt)),3)} -> 0.16
A206: Spritz Sarti Rosa | B206: A Spritz version with Sarti Rosa, an aperitivo crafted with blood orange, mango and passion fruit. | C206: Sarti Rosa – 40 ml Sparkling Wine – 60 ml Club Soda – 20 ml Lime juice – 5 ml | D206: 1 | E206: images/cocktails/spritzsartirosa.jpg | F206: {=ROUND(SUM(_xlfn.LET(_xlpm.lines,_xlfn.TEXTSPLIT(C206,,CHAR(10)),_xlpm.nm,TRIM(_xlfn.TEXTBEFORE(_xlpm.lines," – ")),_xlpm.amt,VALUE(_xlfn.TEXTBEFORE(_xlfn.TEXTAFTER(_xlpm.lines," – ")," ")),_xlpm.abv,_xlfn.IFNA(_xlfn.XLOOKUP(_xlpm.nm,'Alcohol by Category'!$A$13:$A$95,'Alcohol by Category'!$E$13:$E$95),_xlfn.IFNA(_xlfn.XLOOKUP(_xlpm.nm,'Alcohol by Category'!$A$99:$A$107,'Alcohol by Category'!$E$99:$E$107),0)),_xlpm.amt*_xlpm.abv)),1)} -> 12.8 | G206: {=ROUND(F206/SUM(_xlfn.LET(_xlpm.lines,_xlfn.TEXTSPLIT(C206,,CHAR(10)),_xlpm.amt,VALUE(_xlfn.TEXTBEFORE(_xlfn.TEXTAFTER(_xlpm.lines," – ")," ")),_xlpm.amt)),3)} -> 0.102
A207: Spritz Select | B207: A Spritz version with Select, an original Venetian aperitivo crafted with 30 botanicals including juniper berries and rhubarb root for a refined harmony of bitter, floral, and citrus notes. | C207: Select – 40 ml Sparkling Wine – 60 ml Club Soda – 20 ml | D207: 6 | E207: images/cocktails/spritzselect.jpg | F207: {=ROUND(SUM(_xlfn.LET(_xlpm.lines,_xlfn.TEXTSPLIT(C207,,CHAR(10)),_xlpm.nm,TRIM(_xlfn.TEXTBEFORE(_xlpm.lines," – ")),_xlpm.amt,VALUE(_xlfn.TEXTBEFORE(_xlfn.TEXTAFTER(_xlpm.lines," – ")," ")),_xlpm.abv,_xlfn.IFNA(_xlfn.XLOOKUP(_xlpm.nm,'Alcohol by Category'!$A$13:$A$95,'Alcohol by Category'!$E$13:$E$95),_xlfn.IFNA(_xlfn.XLOOKUP(_xlpm.nm,'Alcohol by Category'!$A$99:$A$107,'Alcohol by Category'!$E$99:$E$107),0)),_xlpm.amt*_xlpm.abv)),1)} -> 14.2 | G207: {=ROUND(F207/SUM(_xlfn.LET(_xlpm.lines,_xlfn.TEXTSPLIT(C207,,CHAR(10)),_xlpm.amt,VALUE(_xlfn.TEXTBEFORE(_xlfn.TEXTAFTER(_xlpm.lines," – ")," ")),_xlpm.amt)),3)} -> 0.118
A208: Spritz St Germain (Hugo) | B208: A lighter variation of the Spritz popular in Austria and northern Italy. St. Germain elderflower liqueur replaces the traditional Aperol, combined with sparkling wine and a splash of club soda. | C208: St. Germain – 40 ml Sparkling Wine – 60 ml Club Soda – 20 ml | D208: 6 | E208: images/cocktails/hugo-spritz.jpg | F208: 15.2 | G208: 0.127
A209: Sweet Basil #2 | B209: A cocktail for basil lovers from Todd Thrasher of Restaurant Eve in Alexandria, Virginia. Lillet Blanc, gin, and basil syrup combine for a fragrant, herbaceous, and refreshing drink. | C209: Lillet Blanc – 90 ml Gin – 15 ml Basil Syrup – 30 ml Basil – 1 leaf | D209: 5 | E209: images/cocktails/sweet-basil-2.jpg | F209: 21.3 | G209: 0.158
A210: Tailspin | B210: A variation of the Bijou replacing orange bitters with Campari. Equal parts gin, sweet vermouth, and green Chartreuse are enhanced with a dash of Campari for an herbal, bitter-forward cocktail. | C210: Gin – 20 ml Sweet Vermouth – 20 ml Green Chartreuse – 20 ml Campari – 2.5 ml Lemon – 1 twist Cherry – 1 | D210: 0 | E210: images/cocktails/tailspin.jpg | F210: 22.8 | G210: 0.365
A211: Tampico | B211: A nice long drink created by Rudolf Slavik at the George V Hotel in Paris in 1960. Triple sec, Campari, and lemon juice are topped with tonic water for a refreshingly bitter, citrusy cocktail. | C211: Triple Sec – 20 ml Campari – 30 ml Lemon Juice – 20 ml Tonic Water – 50 ml | D211: 2 | E211: images/cocktails/tampico.jpg | F211: 13.5 | G211: 0.113
...

Sheet Ingredient Usage
A1: Ingredient | B1: Total Quantity Used | C1: Unit | E1: ℹ️ Aggregate ingredient quantities based on each cocktail's recipe × its timesMade count
A2: Ginger Beer | B2: 48600 | C2: ml
A3: Club Soda | B3: 27380 | C3: ml
A4: Vodka | B4: 22740 | C4: ml
A5: Sparkling Wine | B5: 12510 | C5: ml
A6: Gin | B6: 10950 | C6: ml
A7: Lime Juice | B7: 10830 | C7: ml
A8: Lemon Juice | B8: 9631 | C8: ml
A9: Sparkling Water | B9: 8380 | C9: ml
A10: Simple Syrup | B10: 5568 | C10: ml
A11: Ramos Gin Fizz Mix | B11: 5400 | C11: ml
A12: Light Rum | B12: 4395 | C12: ml
A13: Belle De Brillet | B13: 4110 | C13: ml
... A142: Orange | B142: 1 | C142: wedge

Sheet Alcohol by Category
A1: Alcohol Consumption by Category
A3: Category Summary
A4: Category | B4: Total (ml) | C4: Total (L) | D4: Total (bottles ~700ml)
A5: Spirits | B5: 57497.5 | C5: =B5/1000 -> 57.4975 | D5: =B5/700 -> 82.139286
A6: Liqueurs | B6: 21048 | C6: =B6/1000 -> 21.048 | D6: =B6/700 -> 30.068571
A7: Wines & Fortified | B7: 17360 | C7: =B7/1000 -> 17.36 | D7: =B7/700 -> 24.8
A8: Bitters | B8: 0 | C8: =B8/1000 -> 0 | D8: =B8/700 -> 0
A9: TOTAL | B9: =SUM(B5:B8) -> 95905.5 | C9: =B9/1000 -> 95.9055 | D9: =B9/700 -> 137.00786
A11: Spirits | G11: Note: ABV % values are standard/typical bottle strengths used to recompute each cocktail's Alcohol Content (ml) and ABV. Verify against your actual bottles where precision matters.
A12: Ingredient | B12: Total Quantity | C12: Unit | E12: ABV %
A13: Vodka | B13: 22740 | C13: ml | E13: 0.4
A14: Gin | B14: 10950 | C14: ml | E14: 0.4
A15: Light Rum | B15: 4395 | C15: ml | E15: 0.4
A16: Old Tom Gin | B16: 3660 | C16: ml | E16: 0.4
A17: Bourbon | B17: 3200 | C17: ml | E17: 0.4
A18: Scotch Whiskey | B18: 2765 | C18: ml | E18: 0.4
A19: Dark Rum | B19: 1895 | C19: ml | E19: 0.4
A20: Tequila Blanco | B20: 1215 | C20: ml | E20: 0.4
A21: Rye | B21: 1010 | C21: ml | E21: 0.4
A22: Pisco | B22: 840 | C22: ml | E22: 0.4
A23: Cachaca | B23: 780 | C23: ml | E23: 0.4
A24: Mezcal | B24: 730 | C24: ml | E24: 0.4
... A43: Absinthe | B43: 16 | C43: dash | E43: 0.68
A45: Liqueurs
A46: Ingredient | B46: Total Quantity | C46: Unit | E46: ABV %
A47: Belle De Brillet | B47: 4110 | C47: ml | E47: 0.3
A48: Aperol | B48: 4080 | C48: ml | E48: 0.11
A49: Sloe Gin | B49: 3165 | C49: ml | E49: 0.25
A50: Triple Sec | B50: 2185 | C50: ml | E50: 0.3
A51: Campari | B51: 1925 | C51: ml | E51: 0.25
A52: Coffee Liqueur | B52: 540 | C52: ml | E52: 0.2
A53: Raspberry Liqueur | B53: 525 | C53: ml | E53: 0.2
A54: Maraschino Liqueur | B54: 524 | C54: ml | E54: 0.32
A55: Amaretto | B55: 495 | C55: ml | E55: 0.28
A56: Benedictine | B56: 490 | C56: ml | E56: 0.4
A57: Frangelico | B57: 450 | C57: ml | E57: 0.2
A58: St. Germain | B58: 330 | C58: ml | E58: 0.2
... A77: Kahlua | B77: 15 | C77: ml | E77: 0.2
A79: Wines & Fortified
A80: Ingredient | B80: Total Quantity | C80: Unit | E80: ABV %
...
